Workbook
Name Query1: #REF!
Name Query1: #REF!

Sheet Cumulative data
A1: Summary Sheet of First Six Month Transactions
C2: Particulars | D2: Mid Jul 2011-Mid Jan 2012 | F2: Mid Jul 2012-Mid Jan 2013 | H2: Change | I2: Mid Jul 2013-Mid Jan 2014 | K2: Change
D3: 2068/69 | F3: 2069/70 | I3: 2070/71
D4: Share units | E4: Amount | F4: Share units | G4: Amount | H4: in | I4: Share units | J4: Amount | K4: in
D5: ( '000 ) | E5: Rs. in million | F5: ( '000 ) | G5: Rs. in million | H5: % | I5: ( '000 ) | J5: Rs. in million | K5: %
B6: 1 | C6: Turnover | D6: =SUM(D7:D20) -> 20584.08 | E6: =SUM(E7:E20) -> 4406.46 | F6: =SUM(F7:F20) -> 33849.96 | G6: =SUM(G7:G20) -> 9996.25 | H6: =SUM(G6-E6)*100/E6 -> 126.85444 | I6: =SUM(I7:I21) -> 85099.405 | J6: =SUM(J7:J19) -> 28333.207 | K6: =SUM(J6-G6)*100/G6 -> 183.43836
B7: A | C7: Commercial Bank | D7: 4989.31 | E7: 1600.83 | F7: 18993.3 | G7: 6312.67 | H7: =SUM(G7-E7)*100/E7 -> 294.33731 | I7: 40411.71 | J7: 16699.17 | K7: =SUM(J7-G7)*100/G7 -> 164.53418
B8: B | C8: Finance | D8: 1210.26 | E8: 154.33 | F8: 1544.23 | G8: 201.96 | H8: =SUM(G8-E8)*100/E8 -> 30.862438 | I8: 2119.22 | J8: 404.92 | K8: =SUM(J8-G8)*100/G8 -> 100.49515
B9: C | C9: Hotel | D9: 1295.59 | E9: 170.02 | F9: 155.24 | G9: 34.88 | H9: =SUM(G9-E9)*100/E9 -> -79.484766 | I9: 681.15 | J9: 200.28 | K9: =SUM(J9-G9)*100/G9 -> 474.19725
B10: D | C10: Manufacturing & Processing | D10: 1021.08 | E10: 788.46 | F10: 1.98 | G10: 10.68 | H10: =SUM(G10-E10)*100/E10 -> -98.645461 | I10: 621.3 | J10: 88.11 | K10: =SUM(J10-G10)*100/G10 -> 725
B11: E | C11: Other | D11: 137.71 | E11: 57.48 | F11: 632.65 | G11: 389.6 | H11: =SUM(G11-E11)*100/E11 -> 577.80097 | I11: 665.79 | J11: 412.36 | K11: =SUM(J11-G11)*100/G11 -> 5.8418891
B12: F | C12: Hydro Power | D12: 5156.77 | E12: 703.83 | F12: 1773.79 | G12: 1304.36 | H12: =SUM(G12-E12)*100/E12 -> 85.32316 | I12: 4308.97 | J12: 2197.84 | K12: =SUM(J12-G12)*100/G12 -> 68.499494
B13: G | C13: Trading | D13: 1.29 | E13: 3.46 | F13: 1.4 | G13: 2.44 | H13: =SUM(G13-E13)*100/E13 -> -29.479769 | I13: 2.04 | J13: 3.55 | K13: =SUM(J13-G13)*100/G13 -> 45.491803
B14: H | C14: Insurance | D14: 722.59 | E14: 136.27 | F14: 2091.45 | G14: 659.21 | H14: =SUM(G14-E14)*100/E14 -> 383.75284 | I14: 5220.55 | J14: 3184.97 | K14: =SUM(J14-G14)*100/G14 -> 383.14953
B15: I | C15: Development Bank | D15: 2870.17 | E15: 352.37 | F15: 3907.11 | G15: 535.86 | H15: =SUM(G15-E15)*100/E15 -> 52.073105 | I15: 8419.42 | J15: 2034.92 | K15: =SUM(J15-G15)*100/G15 -> 279.74844
B16: J | C16: Mutual Fund | D16: 50.6 | E16: 1.68 | F16: 417.75 | G16: 10.68 | H16: =SUM(G16-E16)*100/E16 -> 535.71429 | I16: 11193.39 | J16: 123.95 | K16: =SUM(J16-G16)*100/G16 -> 1060.5805
B17: K | C17: Preffered Stock | D17: 0.33 | E17: 0.31 | F17: 12.84 | G17: 9.72 | H17: =SUM(G17-E17)*100/E17 -> 3035.4839 | I17: 18.51 | J17: 15.86 | K17: =SUM(J17-G17)*100/G17 -> 63.168724
B18: L | C18: Promotor Share | D18: 3128.38 | E18: 437.42 | F18: 4318.22 | G18: 524.19 | H18: =SUM(G18-E18)*100/E18 -> 19.83677 | I18: 6576.71 | J18: 1606.03 | K18: =SUM(J18-G18)*100/G18 -> 206.38318
C19: Odd-Lot + Mannual Trade | I19: 4860.645 | J19: 1361.2468
C20: Corporate Bond
C21: Government Bond | D21: 1000 | E21: 103
B22: 2 | C22: Market Days | D22: 117 | F22: 115 | I22: 135 | K22: =SUM(I22-F22)*100/F22 -> 17.391304
B23: 3 | C23: Average Daily Turnover | D23: 113.50376 | E23: 29.585726 | F23: =+F7/F22 -> 165.15913 | G23: =+G7/F22 -> 54.892783 | I23: =+I6/I22 -> 630.36596 | J23: =+J6/I22 -> 209.87561 | K23: =SUM(J23-G23)*100/G23 -> 282.33734
B24: 4 | C24: Number of Transactions | D24: 136855 | F24: 155021 | H24: =SUM(F24-D24)*100/D24 -> 13.273903 | I24: 263192 | K24: =SUM(I24-F24)*100/F24 -> 69.778288
B25: 5 | C25: Number of Scrips Traded | D25: 195 | F25: 203 | H25: =SUM(F25-D25)*100/D25 -> 4.1025641 | I25: 230 | K25: =SUM(I25-F25)*100/F25 -> 13.300493
B26: 7 | C26: Number of Companies Listed | D26: 195 | F26: 214 | I26: 234 | K26: =SUM(I26-F26)*100/F26 -> 9.3457944
B27: 8 | C27: Total Paid Up Value of Listed Shares | E27: 93817 | G27: 106449 | H27: =SUM(G27-E27)*100/E27 -> 13.464511 | J27: 136817 | K27: =SUM(J27-G27)*100/G27 -> 28.528215
B28: 9 | C28: Total Number of Listed Securities | D28: 931729 | F28: 1098471 | H28: =SUM(F28-D28)*100/D28 -> 17.895976 | I28: 1418105 | K28: =SUM(I28-F28)*100/F28 -> 29.098083
B29: 10 | C29: Market Capitalization | E29: 349283.36 | G29: 300428.79 | H29: =SUM(G29-E29)*100/E29 -> -13.987088 | J29: 799760.34 | K29: =SUM(J29-G29)*100/G29 -> 166.20629
C30: NEPSE Index
B31: - | C31: High | E31: 472.29 | G31: 380.23 | H31: =SUM(G31-E31)*100/E31 -> -19.492261 | J31: 806.66 | K31: =SUM(J31-G31)*100/G31 -> 112.15054
B32: - | C32: Low | E32: 390.97 | G32: 312.5 | H32: =SUM(G32-E32)*100/E32 -> -20.070594 | J32: 509.36 | K32: =SUM(J32-G32)*100/G32 -> 62.9952
B33: - | C33: Closing | E33: 402.75 | G33: 323.62 | H33: =SUM(G33-E33)*100/E33 -> -19.647424 | J33: 787.05 | K33: =SUM(J33-G33)*100/G33 -> 143.2019
B34: 11 | C34: Market Capitalization of Group -A | E34: 276017.5 | G34: 260732.4 | H34: =SUM(G34-E34)*100/E34 -> -5.5377286 | J34: 647127.66 | K34: =SUM(J34-G34)*100/G34 -> 148.1961
B35: 12 | C35: Total Paid Up Value of Group - A | E35: 45370 | G35: 82240 | H35: =SUM(G35-E35)*100/E35 -> 81.265153 | J35: 97071 | K35: =SUM(J35-G35)*100/G35 -> 18.033804
B36: 13 | C36: NEPSE Sensitive Index
B37: - | C37: High | E37: 114.83 | G37: 94.26 | H37: =SUM(G37-E37)*100/E37 -> -17.913437 | J37: 201.62 | K37: =SUM(J37-G37)*100/G37 -> 113.89773
B38: - | C38: Low | E38: 95.79 | G38: 77.4 | H38: =SUM(G38-E38)*100/E38 -> -19.198246 | J38: 128.3 | K38: =SUM(J38-G38)*100/G38 -> 65.762274
B39: - | C39: Closing | E39: 99.39 | G39: 80.29 | H39: =SUM(G39-E39)*100/E39 -> -19.217225 | J39: 193.38 | K39: =SUM(J39-G39)*100/G39 -> 140.85191
B40: 14 | C40: NEPSE Float Index
...

Sheet Back year's Summary
A1: Comparative Summary Sheet of Transactions with Previous Years
C2: Particulars | D2: Dec-Jan 2012 (Poush 2068) | F2: Dec-Jan 2013 (Poush 2069) | H2: Change | I2: Dec-Jan 2014 (Poush 2070) | K2: Change
D3: Share units | E3: Amount | F3: Share units | G3: Amount | H3: in | I3: Share units | J3: Amount | K3: in
D4: ( '000 ) | E4: Rs. in million | F4: ( '000 ) | G4: Rs. in million | H4: % | I4: ( '000 ) | J4: Rs. in million | K4: %
B5: 1 | C5: Turnover | D5: 3509.8 | E5: 664.87 | F5: ='[1]Summary Sheet'!F8 -> 5484.46 | G5: ='[1]Summary Sheet'!G8 -> 1884.89 | H5: =SUM(G5-E5)*100/E5 -> 183.49753 | I5: ='Summary Sheet'!I8 -> 18093.87 | J5: ='Summary Sheet'!J8 -> 8050.22 | K5: =SUM(J5-G5)*100/G5 -> 327.0923
B6: A | C6: Commercial Bank | D6: 808.16 | E6: 258.86 | F6: ='[1]Summary Sheet'!F9 -> 3952.58 | G6: ='[1]Summary Sheet'!G9 -> 1412.55 | H6: =SUM(G6-E6)*100/E6 -> 445.68106 | I6: ='Summary Sheet'!I9 -> 10445.33 | J6: ='Summary Sheet'!J9 -> 5393.14 | K6: =SUM(J6-G6)*100/G6 -> 281.80171
B7: B | C7: Finance | D7: 217.32 | E7: 24.83 | F7: ='[1]Summary Sheet'!F10 -> 294.31 | G7: ='[1]Summary Sheet'!G10 -> 42.72 | H7: =SUM(G7-E7)*100/E7 -> 72.04994 | I7: ='Summary Sheet'!I10 -> 550.01 | J7: ='Summary Sheet'!J10 -> 131.44 | K7: =SUM(J7-G7)*100/G7 -> 207.6779
B8: C | C8: Hotel | D8: 2.75 | E8: 0.22 | F8: ='[1]Summary Sheet'!F11 -> 33.85 | G8: ='[1]Summary Sheet'!G11 -> 9.22 | H8: =SUM(G8-E8)*100/E8 -> 4090.9091 | I8: ='Summary Sheet'!I11 -> 100.26 | J8: ='Summary Sheet'!J11 -> 31.29 | K8: =SUM(J8-G8)*100/G8 -> 239.37093
B9: D | C9: Manufacturing & Processing | D9: 0.24 | E9: 1.13 | F9: ='[1]Summary Sheet'!F12 -> 0.33 | G9: ='[1]Summary Sheet'!G12 -> 0.75 | H9: =SUM(G9-E9)*100/E9 -> -33.628319 | I9: ='Summary Sheet'!I12 -> 2.24 | J9: ='Summary Sheet'!J12 -> 4.19 | K9: 0
B10: E | C10: Other | D10: 20.25 | E10: 8.7 | F10: ='[1]Summary Sheet'!F13 -> 90.9 | G10: ='[1]Summary Sheet'!G13 -> 60.07 | H10: =SUM(G10-E10)*100/E10 -> 590.45977 | I10: ='Summary Sheet'!I13 -> 244.39 | J10: ='Summary Sheet'!J13 -> 164 | K10: =SUM(J10-G10)*100/G10 -> 173.01482
B11: F | C11: Hydro Power | D11: 1342.35 | E11: 200.8 | F11: ='[1]Summary Sheet'!F14 -> 199.67 | G11: ='[1]Summary Sheet'!G14 -> 173.8 | H11: =SUM(G11-E11)*100/E11 -> -13.446215 | I11: ='Summary Sheet'!I14 -> 760.25 | J11: ='Summary Sheet'!J14 -> 547.05 | K11: =SUM(J11-G11)*100/G11 -> 214.75834
B12: G | C12: Trading | D12: 0.57 | E12: 1.5 | F12: ='[1]Summary Sheet'!F15 -> 0 | G12: ='[1]Summary Sheet'!G15 -> 0 | H12: =SUM(G12-E12)*100/E12 -> -100 | I12: ='Summary Sheet'!I15 -> 1.03 | J12: ='Summary Sheet'!J15 -> 1.8 | K12: 0
B13: H | C13: Insurance | D13: 105.84 | E13: 18.91 | F13: ='[1]Summary Sheet'!F16 -> 185.4 | G13: ='[1]Summary Sheet'!G16 -> 78.73 | H13: =SUM(G13-E13)*100/E13 -> 316.34056 | I13: ='Summary Sheet'!I16 -> 852.77 | J13: ='Summary Sheet'!J16 -> 830.77 | K13: =SUM(J13-G13)*100/G13 -> 955.21402
B14: I | C14: Development Bank | D14: 408.17 | E14: 48.99 | F14: ='[1]Summary Sheet'!F17 -> 549.07 | G14: ='[1]Summary Sheet'!G17 -> 74.88 | H14: =SUM(G14-E14)*100/E14 -> 52.84752 | I14: ='Summary Sheet'!I17 -> 2240.58 | J14: ='Summary Sheet'!J17 -> 573.12 | K14: =SUM(J14-G14)*100/G14 -> 665.38462
B15: J | C15: Mutual Fund | D15: 0 | E15: 0 | F15: ='[1]Summary Sheet'!F18 -> 1.1 | G15: ='[1]Summary Sheet'!G18 -> 0.03 | H15: 0 | I15: ='Summary Sheet'!I18 -> 2403.38 | J15: ='Summary Sheet'!J18 -> 30.5 | K15: =SUM(J15-G15)*100/G15 -> 101566.67
B16: K | C16: Preferred Stock | D16: 0.05 | E16: 0.04 | F16: ='[1]Summary Sheet'!F19 -> 0.54 | G16: ='[1]Summary Sheet'!G19 -> 0.38 | H16: 0 | I16: ='Summary Sheet'!I19 -> 0.01 | J16: ='Summary Sheet'!J19 -> 0.01 | K16: =SUM(J16-G16)*100/G16 -> -97.368421
C17: Promotor Share | D17: 604.1 | E17: 100.89 | F17: ='[1]Summary Sheet'!F20 -> 176.71 | G17: ='[1]Summary Sheet'!G20 -> 31.76 | H17: =SUM(G17-E17)*100/E17 -> -68.52017 | I17: ='Summary Sheet'!I20 -> 493.64 | J17: ='Summary Sheet'!J20 -> 342.92 | K17: =SUM(J17-G17)*100/G17 -> 979.72292
C18: Corporate Bond
C19: Government Bond
B20: 2 | C20: Market days | D20: 19 | F20: ='[1]Summary Sheet'!F23 -> 19 | I20: ='Summary Sheet'!I23 -> 19
B21: 3 | C21: Average daily turnover | D21: 184.72632 | E21: 34.993158 | F21: ='[1]Summary Sheet'!F24 -> 288.65579 | G21: ='[1]Summary Sheet'!G24 -> 99.204737 | I21: ='Summary Sheet'!I24 -> 952.30895 | J21: ='Summary Sheet'!J24 -> 423.69579
B22: 4 | C22: Number of transactions | D22: 28691 | F22: ='[1]Summary Sheet'!F25 -> 24683 | H22: =SUM(F22-D22)*100/D22 -> -13.969537 | I22: ='Summary Sheet'!I25 -> 51614 | K22: =SUM(I22-F22)*100/F22 -> 109.10748
B23: 5 | C23: Number of Scrips Traded | D23: 147 | F23: ='[1]Summary Sheet'!F26 -> 144 | I23: ='Summary Sheet'!I26 -> 161 | K23: =SUM(I23-F23)*100/F23 -> 11.805556
B24: 6 | C24: Number of Companies Listed | D24: 214 | F24: ='[1]Summary Sheet'!F27 -> 221 | I24: ='Summary Sheet'!I27 -> 234 | K24: =SUM(I24-F24)*100/F24 -> 5.8823529
B25: 7 | C25: Total Paid Up Value of Listed Share | E25: 106449 | G25: ='[1]Summary Sheet'!G28 -> 113971 | H25: =SUM(G25-E25)*100/E25 -> 7.0662947 | J25: ='Summary Sheet'!J28 -> 136817 | K25: =SUM(J25-G25)*100/G25 -> 20.04545
B26: 8 | C26: Total Number of Listed Securities | D26: 1098471 | F26: ='[1]Summary Sheet'!F29 -> 1178912 | H26: =SUM(F26-D26)*100/D26 -> 7.3229971 | I26: ='Summary Sheet'!I29 -> 1418105 | K26: =SUM(I26-F26)*100/F26 -> 20.289301
B27: 9 | C27: Market Capitalization | E27: 300428.79 | G27: ='[1]Summary Sheet'!G30 -> 471521.04 | H27: =SUM(G27-E27)*100/E27 -> 56.949352 | J27: ='Summary Sheet'!J30 -> 799760.34 | K27: =SUM(J27-G27)*100/G27 -> 69.612864
B28: 10 | C28: NEPSE Index at the end of Month
B29: - | C29: High | E29: 324.41 | G29: ='[1]Summary Sheet'!G32 -> 501.52 | H29: =SUM(G29-E29)*100/E29 -> 54.594495 | J29: ='Summary Sheet'!J32 -> 806.66 | K29: =SUM(J29-G29)*100/G29 -> 60.843037
B30: - | C30: Low | E30: 312.5 | G30: ='[1]Summary Sheet'!G33 -> 481.94 | H30: =SUM(G30-E30)*100/E30 -> 54.2208 | J30: ='Summary Sheet'!J33 -> 754.09 | K30: =SUM(J30-G30)*100/G30 -> 56.469685
B31: - | C31: Closing | E31: 323.62 | G31: ='[1]Summary Sheet'!G34 -> 497.24 | H31: =SUM(G31-E31)*100/E31 -> 53.649342 | J31: ='Summary Sheet'!J34 -> 787.05 | K31: =SUM(J31-G31)*100/G31 -> 58.283726
B32: 11 | C32: Market Capitalization of Group -A | E32: 260732.4 | G32: ='[1]Summary Sheet'!G35 -> 412442.43 | H32: =SUM(G32-E32)*100/E32 -> 58.186106 | J32: ='Summary Sheet'!J35 -> 647127.66 | K32: =SUM(J32-G32)*100/G32 -> 56.90133
B33: 12 | C33: NEPSE Sensitive Index
B34: - | C34: High | E34: 80.48 | G34: ='[1]Summary Sheet'!G37 -> 127.25 | H34: =SUM(G34-E34)*100/E34 -> 58.113817 | J34: ='Summary Sheet'!J37 -> 201.62 | K34: =SUM(J34-G34)*100/G34 -> 58.444008
B35: - | C35: Low | E35: 77.4 | G35: ='[1]Summary Sheet'!G38 -> 122.82 | H35: =SUM(G35-E35)*100/E35 -> 58.682171 | J35: ='Summary Sheet'!J38 -> 186.42 | K35: =SUM(J35-G35)*100/G35 -> 51.783097
B36: - | C36: Closing | E36: 80.29 | G36: ='[1]Summary Sheet'!G39 -> 126.51 | H36: =SUM(G36-E36)*100/E36 -> 57.566322 | J36: ='Summary Sheet'!J39 -> 193.38 | K36: =SUM(J36-G36)*100/G36 -> 52.857482
B37: 13 | C37: NEPSE Float Index at the end of Month
B38: - | C38: High | E38: 25.87 | G38: ='[1]Summary Sheet'!G41 -> 35.49 | H38: =SUM(G38-E38)*100/E38 -> 37.18593 | J38: ='Summary Sheet'!J41 -> 47.28 | K38: =SUM(J38-G38)*100/G38 -> 33.220626
B39: - | C39: Low | E39: 24.89 | G39: ='[1]Summary Sheet'!G42 -> 34.28 | H39: =SUM(G39-E39)*100/E39 -> 37.725994 | J39: ='Summary Sheet'!J42 -> 44.17 | K39: =SUM(J39-G39)*100/G39 -> 28.850642
B40: - | C40: Closing | E40: 25.69 | G40: ='[1]Summary Sheet'!G43 -> 34.98 | H40: =SUM(G40-E40)*100/E40 -> 36.161931 | J40: ='Summary Sheet'!J43 -> 45.74 | K40: =SUM(J40-G40)*100/G40 -> 30.760435
...

Sheet Summary Sheet
A1: Comparative Summary Sheet of Transactions with Previous Months
A2: Dec 2013-Jan 2014
A3: Poush 2070
C5: Particulars | D5: Oct-Nov 2013 | F5: Nov-Dec 2013 | H5: Change | I5: Dec 2013-Jan 2014 | K5: Change
D6: Share units | E6: Amount | F6: Share units | G6: Amount | H6: in | I6: Share units | J6: Amount | K6: in
D7: ( '000 ) | E7: Rs. in million | F7: ( '000 ) | G7: Rs. in million | H7: % | I7: ( '000 ) | J7: Rs. in million | K7: %
B8: 1 | C8: Turnover | D8: =SUM(D9:D20) -> 5484.46 | E8: =SUM(E9:E20) -> 1884.89 | F8: =SUM(F9:F22) -> 19567.36 | G8: =SUM(G9:G22) -> 6653.72 | H8: =SUM(G8-E8)*100/E8 -> 253.00309 | I8: 18093.87 | J8: 8050.22 | K8: =SUM(J8-G8)*100/G8 -> 20.988259
B9: A | C9: Commercial Bank | D9: 3952.58 | E9: 1412.55 | F9: 11209.51 | G9: 4436.5 | H9: =SUM(G9-E9)*100/E9 -> 214.07738 | I9: 10445.33 | J9: 5393.14 | K9: =SUM(J9-G9)*100/G9 -> 21.562944
B10: B | C10: Finance | D10: 294.31 | E10: 42.72 | F10: 381.91 | G10: 77.09 | H10: =SUM(G10-E10)*100/E10 -> 80.45412 | I10: 550.01 | J10: 131.44 | K10: =SUM(J10-G10)*100/G10 -> 70.502011
B11: C | C11: Hotel | D11: 33.85 | E11: 9.22 | F11: 141.8 | G11: 44.53 | H11: =SUM(G11-E11)*100/E11 -> 382.9718 | I11: 100.26 | J11: 31.29 | K11: =SUM(J11-G11)*100/G11 -> -29.732764
B12: D | C12: Manufacturing & Processing | D12: 0.33 | E12: 0.75 | F12: 2.3 | G12: 4.8 | H12: =SUM(G12-E12)*100/E12 -> 540 | I12: 2.24 | J12: 4.19 | K12: =SUM(J12-G12)*100/G12 -> -12.708333
B13: E | C13: Other | D13: 90.9 | E13: 60.07 | F13: 98.79 | G13: 63.62 | H13: =SUM(G13-E13)*100/E13 -> 5.9097719 | I13: 244.39 | J13: 164 | K13: =SUM(J13-G13)*100/G13 -> 157.78057
B14: F | C14: Hydro Power | D14: 199.67 | E14: 173.8 | F14: 1101.44 | G14: 490.5 | H14: =SUM(G14-E14)*100/E14 -> 182.22094 | I14: 760.25 | J14: 547.05 | K14: =SUM(J14-G14)*100/G14 -> 11.529052
B15: G | C15: Trading | D15: 0 | E15: 0 | F15: 0.4 | G15: 0.69 | H15: 0 | I15: 1.03 | J15: 1.8 | K15: =SUM(J15-G15)*100/G15 -> 160.86957
B16: H | C16: Insurance | D16: 185.4 | E16: 78.73 | F16: 1132.78 | G16: 776.54 | H16: =SUM(G16-E16)*100/E16 -> 886.33304 | I16: 852.77 | J16: 830.77 | K16: =SUM(J16-G16)*100/G16 -> 6.9835424
B17: I | C17: Development Bank | D17: 549.07 | E17: 74.88 | F17: 2082.54 | G17: 525.52 | H17: =SUM(G17-E17)*100/E17 -> 601.81624 | I17: 2240.58 | J17: 573.12 | K17: =SUM(J17-G17)*100/G17 -> 9.0576952
B18: J | C18: Mutual Fund | D18: 1.1 | E18: 0.03 | F18: 2966.26 | G18: 34.03 | H18: =SUM(G18-E18)*100/E18 -> 113333.33 | I18: 2403.38 | J18: 30.5 | K18: =SUM(J18-G18)*100/G18 -> -10.3732
B19: K | C19: Preferred Stock | D19: 0.54 | E19: 0.38 | F19: 0 | G19: 0 | H19: =SUM(G19-E19)*100/E19 -> -100 | I19: 0.01 | J19: 0.01 | K19: 0
C20: Promotor Share | D20: 176.71 | E20: 31.76 | F20: 449.63 | G20: 199.9 | H20: =SUM(G20-E20)*100/E20 -> 529.40806 | I20: 493.64 | J20: 342.92 | K20: =SUM(J20-G20)*100/G20 -> 71.545773
C21: Corporate Bond
C22: Government Bond
B23: 2 | C23: Market days | D23: 19 | F23: 17 | I23: 19
B24: 3 | C24: Average daily turnover | D24: 288.65579 | E24: 99.204737 | F24: 1151.0212 | G24: 391.39529 | I24: =I8/I23 -> 952.30895 | J24: =J8/I23 -> 423.69579
B25: 4 | C25: Number of transactions | D25: 24683 | F25: 45962 | I25: 51614
B26: 5 | C26: Number of Scrips Traded | D26: 144 | F26: 160 | I26: 161
B27: 6 | C27: Number of Companies Listed | D27: 214 | F27: 235 | I27: ='Cumulative data'!I26 -> 234
B28: 7 | C28: Total Paid Up Value of Listed Share | E28: 104809 | G28: 134688 | H28: =SUM(G28-E28)*100/E28 -> 28.508048 | J28: ='Cumulative data'!J27 -> 136817 | K28: =SUM(J28-G28)*100/G28 -> 1.5806902
B29: 8 | C29: Total Number of Listed Securities | D29: 1082061 | F29: 1397818 | H29: =SUM(F29-D29)*100/D29 -> 29.181072 | I29: ='Cumulative data'!I28 -> 1418105 | K29: =SUM(I29-F29)*100/F29 -> 1.4513334
B30: 9 | C30: Market Capitalization | E30: 290340.48 | G30: 744141.31 | H30: =SUM(G30-E30)*100/E30 -> 156.29954 | J30: ='Cumulative data'!J29 -> 799760.34 | K30: =SUM(J30-G30)*100/G30 -> 7.4742568
B31: 10 | C31: NEPSE Index at the end of Month
B32: - | C32: High | E32: 501.52 | G32: 732.95 | H32: =SUM(G32-E32)*100/E32 -> 46.145717 | J32: 806.66 | K32: =SUM(J32-G32)*100/G32 -> 10.056621
B33: - | C33: Low | E33: 481.94 | G33: 633.99 | H33: =SUM(G33-E33)*100/E33 -> 31.54957 | J33: 754.09 | K33: =SUM(J33-G33)*100/G33 -> 18.943516
B34: - | C34: Closing | E34: 316.27 | G34: 732.95 | H34: =SUM(G34-E34)*100/E34 -> 131.74819 | J34: 787.05 | K34: =SUM(J34-G34)*100/G34 -> 7.381131
B35: 11 | C35: Market Capitalization of Group -A | E35: 251359.31 | G35: 607989.63 | H35: =SUM(G35-E35)*100/E35 -> 141.88069 | J35: ='Cumulative data'!J34 -> 647127.66 | K35: =SUM(J35-G35)*100/G35 -> 6.4372852
B36: 12 | C36: NEPSE Sensitive Index
B37: - | C37: High | E37: 127.25 | G37: 181.98 | H37: =SUM(G37-E37)*100/E37 -> 43.009823 | J37: 201.62 | K37: =SUM(J37-G37)*100/G37 -> 10.792395
B38: - | C38: Low | E38: 122.82 | G38: 158.47 | H38: =SUM(G38-E38)*100/E38 -> 29.026217 | J38: 186.42 | K38: =SUM(J38-G38)*100/G38 -> 17.637408
B39: - | C39: Closing | E39: 78.42 | G39: 181.98 | H39: =SUM(G39-E39)*100/E39 -> 132.05815 | J39: 193.38 | K39: =SUM(J39-G39)*100/G39 -> 6.2644247
B40: 13 | C40: NEPSE Sensitive Float Index at the end of Month
B41: - | C41: High | E41: 35.49 | G41: 43.22 | H41: =SUM(G41-E41)*100/E41 -> 21.780783 | J41: 47.28 | K41: =SUM(J41-G41)*100/G41 -> 9.3937992
...

Sheet Companywise Transaction
A1: Company wise Transactions
A2: Dec-Jan 2014
A3: Poush- 2070
B4: Commercial Bank
B5: Name of the company | C5: Traded Share | D5: Traded | E5: Number | J5: Trading
C6: Quantity | D6: Amount | E6: Of | F6: High | G6: Low | H6: Closing | I6: Average | J6: Days
C7: ( in '000) | D7: Rs. In million | E7: Trades | I7: Price
A8: 1 | B8: Agriculture Development Bank Limited | C8: 530.36 | D8: 251.108 | E8: 2937 | F8: 518 | G8: 416 | H8: 501 | I8: 473.47 | J8: 19
A9: 2 | B9: Bank of Kathmandu | C9: 318.77 | D9: 213.82 | E9: 1084 | F9: 742 | G9: 618 | H9: 644 | I9: 670.76 | J9: 19
A10: 3 | B10: Citizens Bank International Limited | C10: 255.12 | D10: 115.13 | E10: 1130 | F10: 502 | G10: 400 | H10: 453 | I10: 451.28 | J10: 19
A11: 4 | B11: Everest Bank Ltd | C11: 106.72 | D11: 238.781 | E11: 677 | F11: 2360 | G11: 2055 | H11: 2210 | I11: 2237.52 | J11: 19
A12: 5 | B12: GRAND Bank Ltd. | C12: 314.38 | D12: 100.71 | E12: 818 | F12: 360 | G12: 285 | H12: 304 | I12: 320.35 | J12: 19
A13: 6 | B13: Himalayan Bank Ltd. | C13: 80.77 | D13: 72.365 | E13: 377 | F13: 973 | G13: 840 | H13: 890 | I13: 895.96 | J13: 19
A14: 7 | B14: Janata Bank Nepal Ltd. | C14: 289.19 | D14: 89.55 | E14: 833 | F14: 350 | G14: 276 | H14: 302 | I14: 309.66 | J14: 19
A15: 8 | B15: Kumari Bank Ltd | C15: 779.61 | D15: 408.407 | E15: 1622 | F15: 593 | G15: 463 | H15: 579 | I15: 523.86 | J15: 19
A16: 9 | B16: KIST Bank Limited | C16: 888.89 | D16: 219.492 | E16: 1276 | F16: 267 | G16: 221 | H16: 234 | I16: 246.93 | J16: 19
A17: 10 | B17: Laxmi Bank Limited | C17: 262.52 | D17: 140.413 | E17: 700 | F17: 584 | G17: 488 | H17: 522 | I17: 534.87 | J17: 19
A18: 11 | B18: Machhachapuchhre Bank Ltd | C18: 539.49 | D18: 231.521 | E18: 1141 | F18: 484 | G18: 368 | H18: 480 | I18: 429.15 | J18: 19
A19: 12 | B19: Mega Bank Nepal Ltd. | C19: 326.29 | D19: 136.847 | E19: 3063 | F19: 475 | G19: 367 | H19: 444 | I19: 419.41 | J19: 19
... A32: 25 | B32: Sunrise Bank Limited | C32: 272.97 | D32: 115.94 | E32: 1288 | F32: 460 | G32: 369 | H32: 445 | I32: 424.74 | J32: 19
A33: 27 | B33: Total | C33: 10445.34 | D33: 5393.138 | E33: 29244
B36: Hotel
B37: Name of the company | C37: Traded Share | D37: Traded | E37: Number | J37: Trading
C38: Quantity | D38: Amount | E38: Of | F38: High | G38: Low | H38: Closing | I38: Average | J38: Days
C39: ( in '000) | D39: Rs. In million | E39: Trades | I39: Price
A40: 1 | B40: Oriental Hotel Ltd. | C40: 27.11 | D40: 7.645 | E40: 185 | F40: 330 | G40: 238 | H40: 290 | I40: 281.99 | J40: 16
A41: 2 | B41: Soaltee Hotel Ltd. | C41: 112.87 | D41: 36.67 | E41: 52 | F41: 375 | G41: 285 | H41: 340 | I41: 324.9 | J41: 11
A42: 3 | B42: Taragaon Regency Hotel | C42: 1.82 | D42: 0.217 | E42: 42 | F42: 130 | G42: 113 | H42: 130 | I42: 119.29 | J42: 10
B43: Total | C43: 141.8 | D43: 44.532 | E43: 279
B46: Mutual Fund
B47: Name of the company | C47: Traded Share | D47: Traded | E47: Number | J47: Trading
C48: Quantity | D48: Amount | E48: Of | F48: High | G48: Low | H48: Closing | I48: Average | J48: Days
C49: ( in '000) | D49: Rs. In million | E49: Trades | I49: Price
A50: 1 | B50: Nabil Balance Fund 1 | C50: 1723.59 | D50: 18.978 | E50: 385 | F50: 12.1 | G50: 10.1 | H50: 11.37 | I50: 11.01 | J50: 17
A51: 2 | B51: Siddhartha Investment Growth Scheme-1 | C51: 1242.67 | D51: 15.056 | E51: 118 | F51: 12.75 | G51: 11.3 | H51: 12 | I51: 12.12 | J51: 16
B52: Total | C52: 2966.26 | D52: 34.034 | E52: 503
B54: Others
B55: Name of the company | C55: Traded Share | D55: Traded | E55: Number | J55: Trading
C56: Quantity | D56: Amount | E56: Of | F56: High | G56: Low | H56: Closing | I56: Average | J56: Days
C57: ( in '000) | D57: Rs. In million | E57: Trades | I57: Price
...

Sheet Transaction of Promotor share
A1: Company wise Transactions of Promotor Share
A2: Dec-Jan 2014
A3: Poush 2070
B4: Promotor Share Transaction
B5: Name of the company | C5: Traded Share | D5: Traded | E5: Number | J5: Trading
C6: Quantity | D6: Amount | E6: of | F6: High | G6: Low | H6: Closing | I6: Average | J6: Days
C7: ( in '000) | D7: Rs.in million | E7: Trades | I7: Price
A8: 1 | B8: Alliance Insurance Company Ltd. Promoter | C8: 14.94 | D8: 1.494 | E8: 1 | F8: 100 | G8: 100 | H8: 100 | I8: 100 | J8: 1
A9: 2 | B9: Citizens Bank International Limited Promoter Share | C9: 46.38 | D9: 163.132 | E9: 5 | F9: 135 | G9: 133 | H9: 133 | I9: 3517.53 | J9: 2
A10: 3 | B10: Kailash Bikas Bank Ltd. Promoter Share | C10: 23 | D10: 4.048 | E10: 4 | F10: 176 | G10: 176 | H10: 176 | I10: 176 | J10: 1
A11: 4 | B11: Kumari Bank Limited Promotor Share | C11: 23.33 | D11: 2.333 | E11: 2 | F11: 100 | G11: 100 | H11: 100 | I11: 100 | J11: 2
A12: 5 | B12: NABIL Bank Limited Promotor Share | C12: 91.91 | D12: 119.523 | E12: 119 | F12: 1455 | G12: 1275 | H12: 1300 | I12: 1300.42 | J12: 18
A13: 6 | B13: Nepal Express Finance Limited Promoter Share | C13: 35.67 | D13: 3.639 | E13: 1 | F13: 102 | G13: 102 | H13: 102 | I13: 102 | J13: 1
A14: 7 | B14: National Life Insurance Co. Ltd. Promoter Share | C14: 20.08 | D14: 12.312 | E14: 2 | F14: 620 | G14: 608 | H14: 608 | I14: 613.13 | J14: 2
A15: 8 | B15: Nepal Life Insurance Co. Ltd. Promoter | C15: 1.88 | D15: 3.234 | E15: 1 | F15: 1725 | G15: 1725 | H15: 1725 | I15: 1725 | J15: 1
A16: 9 | B16: Prime Commercial Bank Ltd. Promoter Share | C16: 208.4 | D16: 30.382 | E16: 18 | F16: 148 | G16: 143 | H16: 148 | I16: 145.78 | J16: 5
A17: 10 | B17: Seti Finance Ltd. Promoter Share | C17: 19.45 | D17: 1.945 | E17: 8 | F17: 100 | G17: 100 | H17: 100 | I17: 100 | J17: 2
A18: 11 | B18: Subbecha Bikas Bank Ltd. Promoter | C18: 8.6 | D18: 0.877 | E18: 1 | F18: 102 | G18: 102 | H18: 102 | I18: 102 | J18: 1
B19: Total | C19: 493.64 | D19: 342.919 | E19: 162

Sheet Market Capitalization
A2: Sectorwise Market Capitalization
A3: Dec-Jan 2014
A4: Date | B4: Com. | C4: Manufact- | D4: Hotel | E4: Others | F4: Hydro | G4: Trading | H4: Insurance | I4: Finance | J4: Dev. | K4: Total
B5: Bank | C5: & Pros. | F5: Power | J5: Bank | K5: Rs. in millions
A6: 41624 | B6: 462958.76 | C6: 16388.025 | D6: 14334.7 | E6: 100518.42 | F6: 50688.359 | G6: 981.77238 | H6: 60887.792 | I6: 27675.861 | J6: 48238.388 | K6: 782672.08
A7: 41626 | B7: 490132.48 | C7: 16388.025 | D7: 14550.397 | E7: 105018.42 | F7: 52680.372 | G7: 998.47999 | H7: 61940.428 | I7: 28220.664 | J7: 49052.139 | K7: 818981.41
A8: 41627 | B8: 487195.15 | C8: 16388.025 | D8: 14976.531 | E8: 105018.42 | F8: 52607.928 | G8: 998.47999 | H8: 62831.014 | I8: 28771.542 | J8: 48859.083 | K8: 817646.17
A9: 41628 | B9: 487195.15 | C9: 16388.025 | D9: 14976.531 | E9: 105018.42 | F9: 52607.928 | G9: 998.47999 | H9: 62831.014 | I9: 27206.995 | J9: 51042.08 | K9: 818264.62
A10: 41630 | B10: 476799.25 | C10: 16388.025 | D10: 15152.041 | E10: 104718.42 | F10: 51455.473 | G10: 998.47999 | H10: 63795.614 | I10: 27388.139 | J10: 50945.771 | K10: 807641.22
A11: 41631 | B11: 454659.96 | C11: 16388.025 | D11: 15071.853 | E11: 99768.423 | F11: 50606.151 | G11: 998.47999 | H11: 65661.737 | I11: 27521.295 | J11: 50476.769 | K11: 781152.69
A12: 41632 | B12: 460106.72 | C12: 16388.025 | D12: 15046.853 | E12: 102018.42 | F12: 50686.297 | G12: 998.47999 | H12: 65993.396 | I12: 27706.357 | J12: 50505.27 | K12: 789449.82
A13: 41634 | B13: 468570.23 | C13: 16576.768 | D13: 15041.954 | E13: 102018.42 | F13: 51163.759 | G13: 998.47999 | H13: 66708.403 | I13: 27633.838 | J13: 51071.435 | K13: 799783.29
A14: 41637 | B14: 465008.8 | C14: 16576.768 | D14: 14665.733 | E14: 100518.42 | F14: 50648.441 | G14: 998.47999 | H14: 65288.02 | I14: 27616.02 | J14: 51121.549 | K14: 792442.23
A15: 41639 | B15: 457809.29 | C15: 16576.768 | D15: 14362.036 | E15: 100368.42 | F15: 49458.822 | G15: 998.47999 | H15: 65259.043 | I15: 27525.388 | J15: 50975.98 | K15: 783334.23
A16: 41640 | B16: 447748.52 | C16: 16576.768 | D16: 14401.936 | E16: 98268.423 | F16: 47921.49 | G16: 998.47999 | H16: 63099.775 | I16: 27471.31 | J16: 50306.184 | K16: 766792.88
A17: 41641 | B17: 452739.24 | C17: 16576.768 | D17: 14892.581 | E17: 100218.42 | F17: 48287.914 | G17: 998.47999 | H17: 64480.621 | I17: 27403.871 | J17: 50203.248 | K17: 775801.14
... A25: 41653 | B25: 463810.2 | C25: 16383.132 | D25: 15000.167 | E25: 100518.42 | F25: 50905.112 | G25: 991.60038 | H25: 70252.013 | I25: 28128.943 | J25: 53770.754 | K25: 799760.34

Sheet Index
A1: NEPSE Index
A2: Dec-Jan 2014
A3: Date | B3: Com. | C3: Manufact- | D3: Hotel | E3: Other | F3: Hydro | G3: Trading | H3: Insurance | I3: Finance | J3: Dev. | K3: NEPSE
B4: Bank | C4: & Pros. | F4: Power | J4: Bank | K4: INDEX
A5: 41624 | B5: 785.79454 | C5: 923.64679 | D5: 1084.3274 | E5: 787.14339 | F5: 1761.8477 | G5: 168.75001 | H5: 1951.6965 | I5: 316.3968 | J5: 422.43796 | K5: 770.89988
A6: 41626 | B6: 831.91735 | C6: 923.64679 | D6: 1100.6435 | E6: 822.38215 | F6: 1831.087 | G6: 171.62177 | H6: 1985.4377 | I6: 322.62511 | J6: 429.56421 | K6: 806.66308
A7: 41627 | B7: 826.93173 | C7: 923.64679 | D7: 1132.8778 | E7: 822.38215 | F7: 1828.5689 | G7: 171.62177 | H7: 2013.9845 | I7: 328.92288 | J7: 427.87356 | K7: 805.34793
A8: 41628 | B8: 826.93173 | C8: 923.64679 | D8: 1132.8778 | E8: 822.38215 | F8: 1828.5689 | G8: 171.62177 | H8: 2013.9845 | I8: 318.10443 | J8: 436.62629 | K8: 805.34859
A9: 41630 | B9: 809.28644 | C9: 923.64679 | D9: 1146.154 | E9: 820.0329 | F9: 1788.5114 | G9: 171.62177 | H9: 2044.9038 | I9: 320.218 | J9: 435.76402 | K9: 794.88389
A10: 41631 | B10: 771.70872 | C10: 923.64679 | D10: 1140.0883 | E10: 781.27026 | F10: 1758.9903 | G10: 171.62177 | H10: 2104.7205 | I10: 321.77484 | J10: 431.73686 | K10: 768.81059
A11: 41632 | B11: 780.95368 | C11: 923.64679 | D11: 1138.1972 | E11: 798.88964 | F11: 1761.7761 | G11: 171.62177 | H11: 2115.3515 | I11: 323.9356 | J11: 431.63076 | K11: 776.90356
A12: 41634 | B12: 795.31906 | C12: 934.28457 | D12: 1137.8266 | E12: 798.88964 | F12: 1778.3719 | G12: 171.62177 | H12: 2138.2703 | I12: 323.08773 | J12: 436.46935 | K12: 787.07281
A13: 41637 | B13: 789.21323 | C13: 934.28457 | D13: 1109.3679 | E13: 787.14339 | F13: 1760.4603 | G13: 171.62177 | H13: 2081.5093 | I13: 322.8794 | J13: 435.99818 | K13: 779.49923
A14: 41639 | B14: 776.99421 | C14: 934.28457 | D14: 1086.3952 | E14: 785.96876 | F14: 1719.111 | G14: 171.62177 | H14: 2080.5854 | I14: 321.82092 | J14: 434.70564 | K14: 770.52978
A15: 41640 | B15: 759.91906 | C15: 934.28457 | D15: 1089.4134 | E15: 769.524 | F15: 1665.6757 | G15: 171.62177 | H15: 1999.4607 | I15: 321.03968 | J15: 428.99623 | K15: 754.08694
A16: 41641 | B16: 769.30809 | C16: 934.28457 | D16: 1126.5275 | E16: 784.79414 | F16: 1678.412 | G16: 171.62177 | H16: 2043.2159 | I16: 320.25157 | J16: 428.11842 | K16: 763.47427
... A24: 41653 | B24: 788.1202 | C24: 923.37102 | D24: 1134.6657 | E24: 787.14339 | F24: 1769.3817 | G24: 170.43928 | H24: 2226.0957 | I24: 328.72502 | J24: 458.54106 | K24: 787.05278

Sheet Sensitive M.Cap
A2: Sectorwise Sensitive Market Capitalization
A3: Dec- Jan 2014
A4: Date | B4: Com. | C4: Man. | D4: Hotel | E4: Others | F4: Insurance | G4: Finance | H4: Hydro | I4: Dev. | J4: Total
B5: Bank | C5: & Processing | H5: Power | I5: Bank | J5: Rs. in millions
A6: 41624 | B6: 420271.95 | C6: 9474.003 | D6: 7564.7574 | E6: 100500 | F6: 23577.661 | G6: 16846.566 | H6: 37296.251 | I6: 25848.615 | J6: 641379.8
A7: 41626 | B7: 444545.07 | C7: 9474.003 | D7: 7736.6837 | E7: 105000 | F7: 24352.629 | G7: 17327.891 | H7: 38609.941 | I7: 26574.864 | J7: 673621.09
A8: 41627 | B8: 442028.79 | C8: 9474.003 | D8: 8016.0639 | E8: 105000 | F8: 24416.985 | G8: 17789.593 | H8: 38352.697 | I8: 26528.94 | J8: 671607.07
A9: 41627 | B9: 442028.79 | C9: 9474.003 | D9: 8016.0639 | E9: 105000 | F9: 24416.985 | G9: 17789.593 | H9: 38352.697 | I9: 28711.938 | J9: 673790.07
A10: 41630 | B10: 431161.66 | C10: 9474.003 | D10: 8166.4994 | E10: 104700 | F10: 23961.232 | G10: 17899.632 | H10: 37794.365 | I10: 28723.592 | J10: 661880.99
A11: 41631 | B11: 411391.93 | C11: 9474.003 | D11: 8145.0087 | E11: 99750 | F11: 23645.581 | G11: 18035.427 | H11: 37313.682 | I11: 28325.882 | J11: 636081.51
A12: 41632 | B12: 416317.34 | C12: 9474.003 | D12: 8145.0087 | E12: 102000 | F12: 23363.086 | G12: 18100.622 | H12: 37408.234 | I12: 28482.912 | J12: 643291.21
A13: 41634 | B13: 423944.32 | C13: 9662.7465 | D13: 8145.0087 | E13: 102000 | F13: 23985.864 | G13: 17983.526 | H13: 37654.386 | I13: 29047.915 | J13: 652423.77
A14: 41637 | B14: 420620.34 | C14: 9662.7465 | D14: 7844.1376 | E14: 100500 | F14: 23735.37 | G14: 17911.028 | H14: 37486.939 | I14: 29003.381 | J14: 646763.94
A15: 41639 | B15: 414686.62 | C15: 9662.7465 | D15: 7586.2482 | E15: 100350 | F15: 23304.096 | G15: 17762.263 | H15: 36348.089 | I15: 28766.286 | J15: 638466.35
A16: 41640 | B16: 405641.54 | C16: 9662.7465 | D16: 7586.2482 | E16: 98250 | F16: 22617.129 | G16: 17688.063 | H16: 34950.938 | I16: 27954.763 | J16: 624351.43
A17: 41641 | B17: 410090.91 | C17: 9662.7465 | D17: 7844.1376 | E17: 100200 | F17: 23118.661 | G17: 17650.072 | H17: 35394.646 | I17: 27608.298 | J17: 631569.47
... A25: 41653 | B25: 419600.06 | C25: 9470.3202 | D25: 7435.8126 | E25: 100500 | F25: 26290.152 | G25: 18387.356 | H25: 35852.088 | I25: 29591.867 | J25: 647127.66

Sheet  Sensitive Index
A2: NEPSE Sensitive-INDEX
A3: Dec-Jan 2014
A4: Date | B4: Com. | C4: Manufact- | D4: Hotel | E4: Others | F4: Insurance | G4: Finance | H4: Hydro | I4: Dev. | J4: Sensitive
B5: Bank | C5: & Pros. | H5: Power | I5: Bank | J5: INDEX
A6: 41624 | B6: 193.35965 | C6: 411.6 | D6: 614.67647 | E6: 172.88315 | F6: 627.04227 | G6: 86.327618 | H6: 448.3299 | I6: 105.30512 | J6: 191.97061
A7: 41626 | B7: 204.52728 | C7: 411.6 | D7: 628.64639 | E7: 180.62419 | F7: 647.65237 | G7: 88.794094 | H7: 464.12148 | I7: 108.2638 | J7: 201.62071
A8: 41627 | B8: 203.36958 | C8: 411.6 | D8: 651.34751 | E8: 180.62419 | F8: 649.36389 | G8: 91.160012 | H8: 461.02921 | I8: 108.07671 | J8: 201.01789
A9: 41628 | B9: 203.36958 | C9: 411.6 | D9: 651.34751 | E9: 180.62419 | F9: 649.36389 | G9: 91.160012 | H9: 461.02921 | I9: 112.01437 | J9: 201.01789
A10: 41630 | B10: 198.36981 | C10: 411.6 | D10: 663.57119 | E10: 180.10812 | F10: 637.24326 | G10: 91.756708 | H10: 454.31762 | I10: 112.04179 | J10: 197.46663
A11: 41631 | B11: 189.27411 | C11: 411.6 | D11: 661.82495 | E11: 171.59298 | F11: 628.84859 | G11: 92.452819 | H11: 448.53944 | I11: 110.80102 | J11: 189.81027
A12: 41632 | B12: 191.5402 | C12: 411.6 | D12: 661.82495 | E12: 175.46349 | F12: 621.3357 | G12: 92.96043 | H12: 449.67603 | I12: 111.24826 | J12: 191.96054
A13: 41634 | B13: 195.04924 | C13: 419.8 | D13: 661.82495 | E13: 175.46349 | F13: 637.89834 | G13: 92.359052 | H13: 452.63497 | I13: 113.45504 | J13: 194.68573
A14: 41637 | B14: 193.50357 | C14: 419.8 | D14: 637.37759 | E14: 172.88315 | F14: 631.23652 | G14: 91.986721 | H14: 450.62212 | I14: 113.2811 | J14: 192.98623
A15: 41639 | B15: 190.7738 | C15: 419.8 | D15: 616.42271 | E15: 172.62511 | F15: 619.76687 | G15: 91.223264 | H15: 436.93227 | I15: 112.70064 | J15: 190.55504
A16: 41640 | B16: 186.61267 | C16: 419.8 | D16: 616.42271 | E16: 169.01263 | F16: 601.49715 | G16: 90.875977 | H16: 420.13743 | I16: 110.05544 | J16: 186.4153
A17: 41641 | B17: 188.90696 | C17: 419.8 | D17: 637.37759 | E17: 172.36708 | F17: 614.83529 | G17: 90.680793 | H17: 425.47114 | I17: 108.69144 | J17: 188.73082
... A25: 41653 | B25: 193.28732 | C25: 411.44 | D25: 604.19903 | E25: 172.88315 | F25: 699.18031 | G25: 94.468736 | H25: 430.96994 | I25: 116.50057 | J25: 193.38005

Sheet Float Index
A2: Float Market Capitalization & INDEX
A3: Dec- Jan 2014
A4: Date | B4: Float M.Ca | C4: Float | D4: Sen. Float M.Ca | E4: Sensitive
B5: Rs. in millions | C5: Index | D5: Rs. in millions | E5: Float Index
A6: 41624 | B6: 155848.17 | C6: 51.6126 | D6: 104083.4 | E6: 45.155418
A7: 41626 | B7: 160666.66 | C7: 53.208352 | D7: 108975.3 | E7: 47.277716
A8: 41627 | B8: 159996.99 | C8: 52.986576 | D8: 108404.73 | E8: 47.030183
A9: 41628 | B9: 159312.99 | C9: 52.986576 | D9: 107720.73 | E9: 47.030182
A10: 41630 | B10: 157447.64 | C10: 52.368278 | D10: 105749.08 | E10: 46.171171
A11: 41631 | B11: 153831.97 | C11: 51.17947 | D11: 102560.69 | E11: 44.801093
A12: 41632 | B12: 154800.14 | C12: 51.501578 | D12: 103172.59 | E12: 45.06839
A13: 41634 | B13: 157171.51 | C13: 52.290526 | D13: 105251.5 | E13: 45.976508
A14: 41639 | B14: 155320.12 | C14: 51.808772 | D14: 104153 | E14: 45.550299
A15: 41640 | B15: 151322 | C15: 50.513349 | D15: 101041.49 | E15: 44.198955
A16: 41641 | B16: 152690.44 | C16: 51.08153 | D16: 101944.39 | E16: 44.740008
A17: 41644 | B17: 151706.25 | C17: 50.752276 | D17: 100881.16 | E17: 44.273392
... A24: 41653 | B24: 157413.35 | C24: 52.661545 | D24: 104215.77 | E24: 45.73684

Sheet Monthly Closing Price
A2: Monhtly Closing Price and Market Capitalization
C3: Nepse | D3: Nepse | E3: Listed | F3: Paid | G3: Total Paid | H3: Today's | I3: Market
B4: Commercial Bank | C4: Code | D4: Code | E4: Shares | F4: UP | G4: Up Value | H4: Closing | I4: Capitalization
D5: No. | F5: Value | H5: Price | I5: 41653
A6: 1 | B6: Nabil Bank Ltd. | C6: NABIL | D6: 102 | E6: 30460518 | F6: 100 | G6: =+E6*F6 -> 3046051800 | H6: 2220 | I6: =SUM(E6*H6) -> 67622349960
A7: 2 | B7: Nepal Investment Bank Ltd. | C7: NIB | D7: 103 | E7: 41448085 | F7: 100 | G7: =+E7*F7 -> 4144808500 | H7: 1010 | I7: =SUM(E7*H7) -> 41862565850
A8: 3 | B8: Standard Chartered Bank Ltd. | C8: SCB | D8: 104 | E8: 20392900 | F8: 100 | G8: =+E8*F8 -> 2039290000 | H8: 1951 | I8: =SUM(E8*H8) -> 39786547900
A9: 4 | B9: Himalayan Bank Ltd. | C9: HBL | D9: 105 | E9: 27600000 | F9: 100 | G9: =+E9*F9 -> 2760000000 | H9: 890 | I9: =SUM(E9*H9) -> 24564000000
A10: 5 | B10: Nepal SBI Bank Limited | C10: SBI | D10: 106 | E10: 26482515 | F10: 100 | G10: =+E10*F10 -> 2648251500 | H10: 1115 | I10: =SUM(E10*H10) -> 29528004225
A11: 6 | B11: Nepal Bangladesh Bank Ltd. | C11: NBB | D11: 107 | E11: 20103890 | F11: 100 | G11: =+E11*F11 -> 2010389000 | H11: 625 | I11: =SUM(E11*H11) -> 12564931250
A12: 7 | B12: Everest Bank Ltd | C12: EBL | D12: 108 | E12: 17612390 | F12: 100 | G12: =+E12*F12 -> 1761239000 | H12: 2210 | I12: =SUM(E12*H12) -> 38923381900
A13: 8 | B13: Bank of Kathmandu | C13: BOK | D13: 109 | E13: 19202122 | F13: 100 | G13: =+E13*F13 -> 1920212200 | H13: 644 | I13: =SUM(E13*H13) -> 12366166568
A14: 9 | B14: NIC Asia Bank Ltd | C14: NICA | D14: 110 | E14: 23115520 | F14: 100 | G14: =+E14*F14 -> 2311552000 | H14: 814 | I14: =SUM(E14*H14) -> 18816033280
A15: 10 | B15: Machhachapuchhre Bank Ltd | C15: MBL | D15: 111 | E15: 24781817 | F15: 100 | G15: =+E15*F15 -> 2478181700 | H15: 480 | I15: =SUM(E15*H15) -> 11895272160
A16: 11 | B16: Laxmi Bank Limited | C16: LBL | D16: 112 | E16: 16941965 | F16: 100 | G16: =+E16*F16 -> 1694196500 | H16: 522 | I16: =SUM(E16*H16) -> 8843705730
A17: 12 | B17: Kumari Bank Ltd | C17: KBL | D17: 113 | E17: 16033128 | F17: 100 | G17: =+E17*F17 -> 1603312800 | H17: 579 | I17: =SUM(E17*H17) -> 9283181112
... A20: 15 | B20: Siddhartha Bank Limited | C20: SBL | D20: 116 | E20: 18135536 | F20: 100 | G20: =+E20*F20 -> 1813553600 | H20: 600 | I20: =SUM(E20*H20) -> 10881321600
A21: 16 | B21: NMB Bank Ltd. | C21: NMB | D21: 117 | E21: 20000000 | F21: 100 | G21: =F21*E21 -> 2000000000 | H21: 420 | I21: =H21*E21 -> 8400000000
A22: 17 | B22: Grand Bank Ltd. | C22: GRAND | D22: 118 | E22: 20000524 | F22: 100 | G22: =F22*E22 -> 2000052400 | H22: 304 | I22: =H22*E22 -> 6080159296
A23: 18 | B23: Global IME Bank Limited | C23: GBIME | D23: 119 | E23: 24181378 | F23: 100 | G23: =F23*E23 -> 2418137800 | H23: 430 | I23: =H23*E23 -> 10397992540
A24: 19 | B24: KIST Bank Limited | C24: KIST | D24: 120 | E24: 20000000 | F24: 100 | G24: =F24*E24 -> 2000000000 | H24: 234 | I24: =H24*E24 -> 4680000000
A25: 20 | B25: Citizens Bank International Ltd. | C25: CZBIL | D25: 121 | E25: 21000000 | F25: 100 | G25: =F25*E25 -> 2100000000 | H25: 453 | I25: =H25*E25 -> 9513000000
A26: 21 | B26: Prime Commercial Bank Limited | C26: PCBL | D26: 123 | E26: 25744458 | F26: 100 | G26: =F26*E26 -> 2574445800 | H26: 508 | I26: =H26*E26 -> 13078184664
A27: 22 | B27: Sunrise Bank Limited | C27: SRBL | D27: 124 | E27: 21125000 | F27: 100 | G27: =F27*E27 -> 2112500000 | H27: 445 | I27: =H27*E27 -> 9400625000
A28: 23 | B28: Agricultural Development Bank Ltd. | C28: ADBL | D28: 125 | E28: 30375000 | F28: 100 | G28: =F28*E28 -> 3037500000 | H28: 501 | I28: =H28*E28 -> 15217875000
A29: 24 | B29: Sanima Bank Ltd. | C29: SANIMA | D29: 126 | E29: 22173636 | F29: 100 | G29: =F29*E29 -> 2217363600 | H29: 524 | I29: =H29*E29 -> 11618985264
A30: 25 | B30: Janata Bank Nepal Ltd | C30: JBNL | D30: 127 | E30: 20600000 | F30: 100 | G30: =F30*E30 -> 2060000000 | H30: 302 | I30: =H30*E30 -> 6221200000
A31: 26 | B31: Nepal Bank Ltd. | C31: NBL | D31: 101 | E31: 40000000 | F31: 100 | G31: =F31*E31 -> 4000000000 | H31: 356 | I31: =H31*E31 -> 14240000000
A32: 27 | B32: Civil Bank Ltd | C32: CBL | D32: 128 | E32: 20000000 | F32: 100 | G32: =F32*E32 -> 2000000000 | H32: 138 | I32: =H32*E32 -> 2760000000
... A34: 29 | B34: Mega Bank Nepal Ltd. | C34: MEGA | D34: 130 | E34: 23300000 | F34: 100 | G34: =F34*E34 -> 2330000000 | H34: 444 | I34: =H34*E34 -> 10345200000
B35: TOTAL | E35: =SUM(E6:E34) -> 661503492 | G35: =SUM(G6:G34) -> 66150349200 | I35: =SUM(I6:I34) -> 463810195279
B36: Manufacturing and Processing
A37: 30 | B37: Bottlers Nepal Ltd.(Balaju) | C37: BNL | D37: 206 | E37: 1948887 | F37: 100 | G37: =+E37*F37 -> 194888700 | H37: 1680 | I37: =SUM(E37*H37) -> 3274130160
A38: 31 | B38: Nepal Lube Oil Ltd. | C38: NLO | D38: 208 | E38: 203936 | F38: 100 | G38: =+E38*F38 -> 20393600 | H38: 242 | I38: =SUM(E38*H38) -> 49352512
A39: 32 | B39: Nepal Vanaspati Ghee Udhyog Ltd | C39: NVG | D39: 209 | E39: 101250 | F39: 100 | G39: =+E39*F39 -> 10125000 | H39: 300 | I39: =SUM(E39*H39) -> 30375000
A40: 33 | B40: Raghupati Jute Mills Ltd. | C40: RJM | D40: 210 | E40: 1806966 | F40: 100 | G40: =+E40*F40 -> 180696600 | H40: 100 | I40: =SUM(E40*H40) -> 180696600
A41: 34 | B41: Butwal Spinning Mills Ltd. | C41: BSM | D41: 211 | E41: 1306693 | F41: 100 | G41: =+E41*F41 -> 130669300 | H41: 18 | I41: =SUM(E41*H41) -> 23520474
A42: 35 | B42: Gorakhakali Rubber Udhyog Ltd. | C42: GRU | D42: 212 | E42: 3833400 | F42: 75 | G42: =+E42*F42 -> 287505000 | H42: 38 | I42: =SUM(E42*H42) -> 145669200
A43: 36 | B43: Jyoti Spinning Mills Ltd (ord.) | C43: JSM | D43: 213 | E43: 1270288 | F43: 100 | G43: =+E43*F43 -> 127028800 | H43: 27 | I43: =SUM(E43*H43) -> 34297776
A44: 37 | B44: Arun Vanaspati Udhyog Ltd. | C44: AVU | D44: 214 | E44: 550343 | F44: 100 | G44: =+E44*F44 -> 55034300 | H44: 58 | I44: =SUM(E44*H44) -> 31919894
...

Sheet Top Ten
A1: List of Top Ten Companies
A2: Dec-Jan 2014
A3: On the Basis of Traded Amount
A4: SN | C4: Name of the Companies | D4: Amount Traded
D5: Rs. in million
B6: 1 | C6: Nepal Bangladesh Bank Ltd. | D6: 699.66
B7: 2 | C7: Nepal Bank Limited | D7: 571.36
B8: 3 | C8: Kumari Bank Ltd | D8: 408.41
B9: 4 | C9: NIC Asia Bank Ltd. | D9: 344.66
B10: 5 | C10: Sanima Bank Ltd. | D10: 322.71
B11: 6 | C11: Nepal Credit And Com. Bank | D11: 308.22
B12: 7 | C12: Chilime Hydro power Co. | D12: 271.55
B13: 8 | C13: Agriculture Development Bank | D13: 251.11
B14: 9 | C14: Everest Bank Ltd. | D14: 238.78
B15: 10 | C15: Machhapuchhre Bank Ltd. | D15: 231.52
A37: On the Basis of Number of Shares Traded
A38: SN | C38: Name of the Companies | D38: No Of Share
D39: (Traded in '000)
B40: 1 | C40: Nabil Balance Fund 1 | D40: 1672.61
B41: 2 | C41: Nepal Bank Limited | D41: 1624.74
B42: 3 | C42: Nepal Bangladesh Bank Ltd. | D42: 1099.39
B43: 4 | C43: Kist Bank Ltd. | D43: 888.89
B44: 5 | C44: Kumari Bank Ltd | D44: 779.61
B45: 6 | C45: Nepal Credit And Com. Bank | D45: 732.86
B46: 7 | C46: Siddhartha Inv. Growth Scheme-1 | D46: 730.77
B47: 8 | C47: Sanima Bank Ltd. | D47: 635.05
B48: 9 | C48: Machhapuchhre Bank Ltd. | D48: 539.49
B49: 10 | C49: Agriculture Development Bank | D49: 530.36
A81: On the Basis of Number of Transactions
A82: SN | C82: Name of the Companies | D82: No of Transactions
B84: 1 | C84: Mega Bank Nepal Ltd. | D84: 3063
B85: 2 | C85: Agriculture Development Bank Limited | D85: 2937
B86: 3 | C86: Nepal Bangladesh Bank Ltd. | D86: 2184
B87: 4 | C87: NIC Asia Bank Ltd. | D87: 1742
B88: 5 | C88: Rural Microfinance Dev Centre Ltd. | D88: 1723
B89: 6 | C89: Nepal Bank Limited | D89: 1684
B90: 7 | C90: Kumari Bank Ltd | D90: 1622
B91: 8 | C91: Apex Development Bank Ltd. | D91: 1620
B92: 9 | C92: Sana Kisan Bikas Bank Ltd | D92: 1577
B93: 10 | C93: Nepal Credit And Com. Bank | D93: 1472
...
